<?xml version="1.0" ?>
    <robot name='niryo_ned2'>
      <link name='world'/>
      <link name='base_link'>
        <inertial>
          <origin xyz="-0.002408 -0.005918 0.051577" rpy="0 0 0"/>
          <mass value="0.999243"/>
          <inertia ixx="0.002" ixy="0" ixz="0" iyy="0.002" iyz="0" izz="0.004"/>
        </inertial>
        <collision name='base_link_collision'>
          <origin xyz="0 0 0" rpy="0 0 0"/>
          <geometry>
            <mesh filename="file:///home/tommaso/lab_ROS2/ws_moveit2/install/niryo_robot_description/share/niryo_robot_description/meshes/ned2/stl/base_link.stl"/>
          </geometry>
        </collision>
        <visual>
          <origin rpy="0 0 0" xyz="0 0 0"/>
          <geometry>
            <mesh filename="file:///home/tommaso/lab_ROS2/ws_moveit2/install/niryo_robot_description/share/niryo_robot_description/meshes/ned2/collada/base_link.dae"/>
          </geometry>
        </visual>
      </link>

      <joint name='joint_world' type='fixed'>
        <parent link="world"/>
        <child link="base_link"/>
        <origin xyz="0 0 0" rpy="0 0 0"/>
      </joint>

      <link name='shoulder_link'>
        <inertial>
           <origin xyz="-0.030731 0.005811 0.030228" rpy="0 0 0"/>
           <mass value="0.474559"/>
           <inertia ixx="0.0015" ixy="0" ixz="0" iyy="0.0015" iyz="0" izz="0.0015"/>
        </inertial>
        <collision name="shoulder_link_collision">
          <origin xyz="0 0 0" rpy="0 0 0"/>
          <geometry>
              <mesh filename="file:///home/tommaso/lab_ROS2/ws_moveit2/install/niryo_robot_description/share/niryo_robot_description/meshes/ned2/stl/shoulder_link.stl"/>
          </geometry>
        </collision>
        <visual name="shoulder_link_visual">
          <origin xyz="0 0 0" rpy="0 0 -1.57"/>
          <geometry>
            <mesh filename="file:///home/tommaso/lab_ROS2/ws_moveit2/install/niryo_robot_description/share/niryo_robot_description/meshes/ned2/collada/shoulder_link.dae"/>
          </geometry>
       </visual>
      </link>

      <joint name='joint_1' type='revolute'>
        <parent link="base_link"/>
        <child link="shoulder_link"/>
        <origin xyz="0 0 0.1065" rpy="0 0 0"/>
        <axis xyz="0 0 1"/>
        <limit lower="-2.96706" upper="2.96706" effort="10" velocity="2.2"/>
      </joint>

      <link name='arm_link'>
        <inertial>
          <origin xyz="0.116485 -0.001412 -0.003381" rpy="0 0 0" />
          <mass value="0.513332" />
          <inertia ixx="0.0015" ixy="0" ixz="0" iyy="0.0015" iyz="0" izz="0.0015" />
        </inertial>
        <collision name='arm_link_collision'>
          <origin xyz="0 0 0" rpy="0 0 0" />
          <geometry>
            <mesh filename="file:///home/tommaso/lab_ROS2/ws_moveit2/install/niryo_robot_description/share/niryo_robot_description/meshes/ned2/stl/arm_link.stl"/>
          </geometry>
        </collision>
        <visual name='arm_link_visual'>
          <origin xyz="0 0 0" rpy="0 3.14 -1.57" />
          <geometry>
            <mesh filename="file:///home/tommaso/lab_ROS2/ws_moveit2/install/niryo_robot_description/share/niryo_robot_description/meshes/ned2/collada/arm_link.dae"/>
          </geometry>
        </visual>
      </link>

      <joint name='joint_2' type='revolute'>
        <parent link="shoulder_link" />
        <child link="arm_link" />
        <origin xyz="0 0 0.1715" rpy="-1.57079 -1.57079 3.14159" />
        <axis xyz="0 -1 0" />
        <limit lower="-1.91009" upper="0.610167" effort="10" velocity="2.2" />
      </joint>

      <link name='elbow_link'>
        <inertial>
          <origin xyz="0.008405 0.023513 0.001398" rpy="0 0 0" />
          <mass value="0.201039" />
          <inertia ixx="0.0015" ixy="0" ixz="0" iyy="0.0015" iyz="0" izz="0.0015" />
        </inertial>
        <collision name='elbow_link_collision'>
          <origin xyz="0 0 0" rpy="0 0 0" />
          <geometry>
            <mesh filename="file:///home/tommaso/lab_ROS2/ws_moveit2/install/niryo_robot_description/share/niryo_robot_description/meshes/ned2/stl/elbow_link.stl"/>
          </geometry>
        </collision>
        <visual name='elbow_link_visual'>
           <origin xyz="0 0 0" rpy="0 0 0" />
           <geometry>
             <mesh filename="file:///home/tommaso/lab_ROS2/ws_moveit2/install/niryo_robot_description/share/niryo_robot_description/meshes/ned2/collada/elbow_link.dae"/>
           </geometry>
        </visual>
      </link>

      <joint name='joint_3' type='revolute'>
        <parent link="arm_link" />
        <child link="elbow_link" />
        <origin xyz="0.012 0 0.3925" rpy="1.5708 0 0" />
        <axis xyz="0 -1 0" />
        <limit lower="-1.34006" upper="1.5701" effort="7" velocity="2" />
      </joint>

      <link name='forearm_link'>
        <inertial>
          <origin xyz="-0.008113 -0.000136 0.107402" rpy="0 0 0" />
          <mass value="0.407088" />
          <inertia ixx="0.003" ixy="0" ixz="0" iyy="0.003" iyz="0" izz="0.003" />
        </inertial>
        <collision name='forearm_link_collision'>
          <origin xyz="0 0 0" rpy="0 0 0" />
          <geometry>
            <mesh filename="file:///home/tommaso/lab_ROS2/ws_moveit2/install/niryo_robot_description/share/niryo_robot_description/meshes/ned2/stl/forearm_link.stl"/>
          </geometry>
        </collision>

        <!--DA VERIFICARE-->
        <collision name='forearm_link_fixed_joint_lump__joint5_motor_collision_1'>
          <origin xyz="-0.045 0 0.1765" rpy="0 0 0" />
          <geometry>
            <box size="0.0435 0.0285 0.0465" />
          </geometry>
        </collision>

        <visual name='forearm_link_visual'>
          <origin xyz="0 0 0" rpy="0 0 0" />
          <geometry>
            <mesh filename="file:///home/tommaso/lab_ROS2/ws_moveit2/install/niryo_robot_description/share/niryo_robot_description/meshes/ned2/collada/forearm_link.dae"/>
          </geometry>
        </visual>
      </link>

      <joint name='joint_4' type='revolute'>
        <parent link="elbow_link" />
        <child link="forearm_link" />
        <origin xyz="0.059 0 0.425" rpy="1.5708 0 1.5708" />
        <axis xyz="1 0 0" />
        <limit lower="-2.09003" upper="2.09003" effort="7" velocity="2" />
      </joint>

      <link name='wrist_link'>
        <inertial>
          <origin xyz="-0.019323 -0.00157 0.000276" rpy="0 0 0" />
          <mass value="0.0403595" />
          <inertia ixx="0.0015" ixy="0" ixz="0" iyy="0.0015" iyz="0" izz="0.0015" />
        </inertial>
        <collision name='wrist_link_collision'>
          <origin xyz="0 0 0" rpy="0 0 0" />
          <geometry>
            <mesh filename="file:///home/tommaso/lab_ROS2/ws_moveit2/install/niryo_robot_description/share/niryo_robot_description/meshes/ned2/stl/wrist_link.stl"/>
          </geometry>
        </collision>
        <visual name='wrist_link_visual'>
          <origin xyz="0 0 0" rpy="0 0 0" />
          <geometry>
            <mesh filename="file:///home/tommaso/lab_ROS2/ws_moveit2/install/niryo_robot_description/share/niryo_robot_description/meshes/ned2/collada/wrist_link.dae"/>
          </geometry>
        </visual>

        <!--DA VERIFICARE-->
        <visual name='wrist_link_fixed_joint_lump__camera_link_visual_1'>
          <origin xyz="0 0.0385 0" rpy="-1.5708 0 0" />
          <geometry>
            <box size="0.01 0.037 0.037" />
          </geometry>
          <material name="DarkGrey">
           <color rgba="0.3 0.3 0.3 1" />
          </material>
        </visual>
      </link>

      <joint name='joint_5' type='revolute'>
        <parent link="forearm_link" />
        <child link="wrist_link" />
        <origin xyz="0.247 0 0.425" rpy="1.5708 0 0" />
        <axis xyz="0 -1 0" />
        <limit lower="-1.92004" upper="1.05016" effort="6" velocity="2" />
      </joint>

      <link name='hand_link'>
        <inertial>
          <origin xyz="0.001497 0.000122 0.009475" rpy="0 0 0" />
          <mass value="0.015877" />
          <inertia ixx="0.00150111" ixy="-4.80106e-08" ixz="-2.33074e-07" iyy="0.00150163" iyz="-2.11326e-08" izz="0.00150153" />
        </inertial>
        <collision name='hand_link_collision'>
          <origin xyz="0 0 0" rpy="0 0 0" />
          <geometry>
            <mesh filename="file:///home/tommaso/lab_ROS2/ws_moveit2/install/niryo_robot_description/share/niryo_robot_description/meshes/ned2/stl/hand_link.stl"/>
          </geometry>
        </collision>
        <visual name='hand_link_visual'>
          <origin xyz="0 0 0" rpy="0 0 0" />
          <geometry>
            <mesh filename="file:///home/tommaso/lab_ROS2/ws_moveit2/install/niryo_robot_description/share/niryo_robot_description/meshes/ned2/collada/hand_link.dae"/>
          </geometry>
        </visual>
      </link>

      <joint name='joint_6' type='revolute'>
        <parent link="wrist_link" />
        <child link="hand_link" />
        <origin xyz="0.2667 0 0.43425" rpy="1.5708 0 1.5708"/>
        <axis xyz="1 0 0" />
        <limit lower="-2.53003" upper="2.53003" effort="5" velocity="2" />
      </joint>
    </robot>
